Exception ignored in: <bound method _DataLoaderIter.__del__ of <torch.utils.data.dataloader._DataLoaderIter object at 0x7fb408828da0>>
Traceback (most recent call last):
  File "/home/sdas/anaconda2/envs/torch_4/lib/python3.6/site-packages/torch/utils/data/dataloader.py", line 349, in __del__
    self._shutdown_workers()
  File "/home/sdas/anaconda2/envs/torch_4/lib/python3.6/site-packages/torch/utils/data/dataloader.py", line 328, in _shutdown_workers
    self.worker_result_queue.get()
  File "/home/sdas/anaconda2/envs/torch_4/lib/python3.6/multiprocessing/queues.py", line 337, in get
    return _ForkingPickler.loads(res)
  File "/home/sdas/anaconda2/envs/torch_4/lib/python3.6/site-packages/torch/multiprocessing/reductions.py", line 70, in rebuild_storage_fd
    fd = df.detach()
  File "/home/sdas/anaconda2/envs/torch_4/lib/python3.6/multiprocessing/resource_sharer.py", line 57, in detach
    with _resource_sharer.get_connection(self._id) as conn:
  File "/home/sdas/anaconda2/envs/torch_4/lib/python3.6/multiprocessing/resource_sharer.py", line 87, in get_connection
    c = Client(address, authkey=process.current_process().authkey)
  File "/home/sdas/anaconda2/envs/torch_4/lib/python3.6/multiprocessing/connection.py", line 494, in Client
    deliver_challenge(c, authkey)
  File "/home/sdas/anaconda2/envs/torch_4/lib/python3.6/multiprocessing/connection.py", line 722, in deliver_challenge
    response = connection.recv_bytes(256)        # reject large message
  File "/home/sdas/anaconda2/envs/torch_4/lib/python3.6/multiprocessing/connection.py", line 216, in recv_bytes
    buf = self._recv_bytes(maxlength)
  File "/home/sdas/anaconda2/envs/torch_4/lib/python3.6/multiprocessing/connection.py", line 407, in _recv_bytes
    buf = self._recv(4)
  File "/home/sdas/anaconda2/envs/torch_4/lib/python3.6/multiprocessing/connection.py", line 383, in _recv
    raise EOFError
EOFError: 
## OAR [2019-09-06 20:17:41] Job 9694950 KILLED ##
